Workbook

Sheet Estanques
A1: dispositivo | B1: fecha | C1: Dias | D1: M3 dia | E1: tarifa | F1: Fecha y Hora de alerta | G1: M3 Alerta
A2: martesatriz Principal Bupa | B2: 45945 | C2: =TEXT(B2,"dddd") -> miércoles | D2: 361.35 | E2: 0
A3: martesatriz Principal Bupa | B3: 45946 | C3: =TEXT(B3,"dddd") -> jueves | D3: 348.36 | E3: 0 | J3: TOTAL | M3: PROMEDIO
A4: martesatriz Principal Bupa | B4: 45947 | C4: =TEXT(B4,"dddd") -> viernes | D4: 363.25 | E4: 0 | I4: lunes | J4: =SUMIF($C$2:$C$77,I4,$D$2:$D$77) -> 4118.14 | L4: lunes | M4: =AVERAGEIF($C$2:$C$77,L4,$D$2:$D$77) -> 374.37636
A5: martesatriz Principal Bupa | B5: 45948 | C5: =TEXT(B5,"dddd") -> sábado | D5: 179.37 | E5: 0 | I5: martes | J5: =SUMIF($C$2:$C$77,I5,$D$2:$D$77) -> 3725.14 | L5: martes | M5: =AVERAGEIF($C$2:$C$77,L5,$D$2:$D$77) -> 372.514
A6: martesatriz Principal Bupa | B6: 45949 | C6: =TEXT(B6,"dddd") -> domingo | D6: 292.89 | E6: 0 | I6: miércoles | J6: =SUMIF($C$2:$C$77,I6,$D$2:$D$77) -> 4165.02 | L6: miércoles | M6: =AVERAGEIF($C$2:$C$77,L6,$D$2:$D$77) -> 378.63818
A7: martesatriz Principal Bupa | B7: 45950 | C7: =TEXT(B7,"dddd") -> lunes | D7: 361.29 | E7: 0 | I7: jueves | J7: =SUMIF($C$2:$C$77,I7,$D$2:$D$77) -> 4150.98 | L7: jueves | M7: =AVERAGEIF($C$2:$C$77,L7,$D$2:$D$77) -> 377.36182
A8: martesatriz Principal Bupa | B8: 45951 | C8: =TEXT(B8,"dddd") -> martes | D8: 348.09 | E8: 0 | I8: viernes | J8: =SUMIF($C$2:$C$77,I8,$D$2:$D$77) -> 4138.91 | L8: viernes | M8: =AVERAGEIF($C$2:$C$77,L8,$D$2:$D$77) -> 376.26455
A9: martesatriz Principal Bupa | B9: 45952 | C9: =TEXT(B9,"dddd") -> miércoles | D9: 342.87 | E9: 0 | I9: sábado | J9: =SUMIF($C$2:$C$77,I9,$D$2:$D$77) -> 3098.17 | L9: sábado | M9: =AVERAGEIF($C$2:$C$77,L9,$D$2:$D$77) -> 281.65182
A10: martesatriz Principal Bupa | B10: 45953 | C10: =TEXT(B10,"dddd") -> jueves | D10: 354.91 | E10: 0 | I10: domingo | J10: =SUMIF($C$2:$C$77,I10,$D$2:$D$77) -> 2741.07 | L10: domingo | M10: =AVERAGEIF($C$2:$C$77,L10,$D$2:$D$77) -> 249.18818
A11: martesatriz Principal Bupa | B11: 45954 | C11: =TEXT(B11,"dddd") -> viernes | D11: 359.3 | E11: 0
A12: martesatriz Principal Bupa | B12: 45955 | C12: =TEXT(B12,"dddd") -> sábado | D12: 306.59 | E12: 0 | I12: Consumo total | J12: =SUM($D$2:$D$77) -> 26137.43
A13: martesatriz Principal Bupa | B13: 45956 | C13: =TEXT(B13,"dddd") -> domingo | D13: 281.27 | E13: 0 | I13: Promedio driario | J13: =AVERAGE($D$2:$D$77) -> 343.91355
A14: martesatriz Principal Bupa | B14: 45957 | C14: =TEXT(B14,"dddd") -> lunes | D14: 375.9 | E14: 0 | I14: MAX | J14: =MAX($D$2:$D$77) -> 524.19
A15: martesatriz Principal Bupa | B15: 45958 | C15: =TEXT(B15,"dddd") -> martes | D15: 374.7 | E15: 0 | I15: MIN | J15: =MIN($D$2:$D$77) -> 149.68
A16: martesatriz Principal Bupa | B16: 45959 | C16: =TEXT(B16,"dddd") -> miércoles | D16: 402.6 | E16: 0
A17: martesatriz Principal Bupa | B17: 45960 | C17: =TEXT(B17,"dddd") -> jueves | D17: 368.59 | E17: 0
A18: martesatriz Principal Bupa | B18: 45961 | C18: =TEXT(B18,"dddd") -> viernes | D18: 230.23 | E18: 0
A19: martesatriz Principal Bupa | B19: 45962 | C19: =TEXT(B19,"dddd") -> sábado | D19: 220.85 | E19: 0
A20: martesatriz Principal Bupa | B20: 45963 | C20: =TEXT(B20,"dddd") -> domingo | D20: 282.2 | E20: 0
A21: martesatriz Principal Bupa | B21: 45964 | C21: =TEXT(B21,"dddd") -> lunes | D21: 355.19 | E21: 0
A22: martesatriz Principal Bupa | B22: 45965 | C22: =TEXT(B22,"dddd") -> martes | D22: 381.3 | E22: 0
A23: martesatriz Principal Bupa | B23: 45966 | C23: =TEXT(B23,"dddd") -> miércoles | D23: 491.53 | E23: 0
A24: martesatriz Principal Bupa | B24: 45967 | C24: =TEXT(B24,"dddd") -> jueves | D24: 338.37 | E24: 0
A25: martesatriz Principal Bupa | B25: 45968 | C25: =TEXT(B25,"dddd") -> viernes | D25: 334.52 | E25: 0
A26: martesatriz Principal Bupa | B26: 45969 | C26: =TEXT(B26,"dddd") -> sábado | D26: 305.46 | E26: 0
A27: martesatriz Principal Bupa | B27: 45970 | C27: =TEXT(B27,"dddd") -> domingo | D27: 154.44 | E27: 0
... A32: martesatriz Principal Bupa | B32: 45975 | C32: =TEXT(B32,"dddd") -> viernes | D32: 351.52 | E32: 0
A33: martesatriz Principal Bupa | B33: 45976 | C33: =TEXT(B33,"dddd") -> sábado | D33: 175.6 | E33: 0 | K33: Consumo M3 por dia
A34: martesatriz Principal Bupa | B34: 45977 | C34: =TEXT(B34,"dddd") -> domingo | D34: 283.37 | E34: 0
A35: martesatriz Principal Bupa | B35: 45978 | C35: =TEXT(B35,"dddd") -> lunes | D35: 377.93 | E35: 0
A36: martesatriz Principal Bupa | B36: 45979 | C36: =TEXT(B36,"dddd") -> martes | D36: 381.23 | E36: 0
A37: martesatriz Principal Bupa | B37: 45980 | C37: =TEXT(B37,"dddd") -> miércoles | D37: 446.84 | E37: 0
A38: martesatriz Principal Bupa | B38: 45981 | C38: =TEXT(B38,"dddd") -> jueves | D38: 366.87 | E38: 0
A39: martesatriz Principal Bupa | B39: 45982 | C39: =TEXT(B39,"dddd") -> viernes | D39: 524.19 | E39: 0
A40: martesatriz Principal Bupa | B40: 45983 | C40: =TEXT(B40,"dddd") -> sábado | D40: 323.02 | E40: 0
A41: martesatriz Principal Bupa | B41: 45984 | C41: =TEXT(B41,"dddd") -> domingo | D41: 164.17 | E41: 0
A42: martesatriz Principal Bupa | B42: 45985 | C42: =TEXT(B42,"dddd") -> lunes | D42: 483.9 | E42: 0
A43: martesatriz Principal Bupa | B43: 45986 | C43: =TEXT(B43,"dddd") -> martes | D43: 361.6 | E43: 0
A44: martesatriz Principal Bupa | B44: 45987 | C44: =TEXT(B44,"dddd") -> miércoles | D44: 338.34 | E44: 0
...

Sheet Torre A
A1: dispositivo | B1: fecha | C1: Dias | D1: m3 dia | E1: tarifa | F1: Fecha y Hora de alerta | G1: M3 Alerta
A2: Torre A Bupa | B2: 45945 | C2: =TEXT(B2,"dddd") -> miércoles | D2: 0.89 | E2: 0 | F2: 45945.875 | G2: 11 | J2: TOTAL | M2: PROMEDIO
A3: Torre A Bupa | B3: 45946 | C3: =TEXT(B3,"dddd") -> jueves | D3: 1.68 | E3: 0 | I3: lunes | J3: =SUMIF($C$2:$C$77,I3,$D$2:$D$77) -> 14.68 | L3: lunes | M3: =AVERAGEIF($C$2:$C$77,L3,$D$2:$D$77) -> 1.3345455
A4: Torre A Bupa | B4: 45947 | C4: =TEXT(B4,"dddd") -> viernes | D4: 0.48 | E4: 0 | F4: 45947.375 | G4: 11 | I4: martes | J4: =SUMIF($C$2:$C$77,I4,$D$2:$D$77) -> 25.24 | L4: martes | M4: =AVERAGEIF($C$2:$C$77,L4,$D$2:$D$77) -> 2.524
A5: Torre A Bupa | B5: 45948 | C5: =TEXT(B5,"dddd") -> sábado | D5: 0.19 | E5: 0 | F5: 45948.625 | G5: 11 | I5: miércoles | J5: =SUMIF($C$2:$C$77,I5,$D$2:$D$77) -> 51.85 | L5: miércoles | M5: =AVERAGEIF($C$2:$C$77,L5,$D$2:$D$77) -> 4.7136364
A6: Torre A Bupa | B6: 45949 | C6: =TEXT(B6,"dddd") -> domingo | D6: 0.37 | E6: 0 | I6: jueves | J6: =SUMIF($C$2:$C$77,I6,$D$2:$D$77) -> 23.7 | L6: jueves | M6: =AVERAGEIF($C$2:$C$77,L6,$D$2:$D$77) -> 2.1545455
A7: Torre A Bupa | B7: 45950 | C7: =TEXT(B7,"dddd") -> lunes | D7: 0.67 | E7: 0 | I7: viernes | J7: =SUMIF($C$2:$C$77,I7,$D$2:$D$77) -> 8.97 | L7: viernes | M7: =AVERAGEIF($C$2:$C$77,L7,$D$2:$D$77) -> 0.81545455
A8: Torre A Bupa | B8: 45951 | C8: =TEXT(B8,"dddd") -> martes | D8: 0.79 | E8: 0 | I8: sábado | J8: =SUMIF($C$2:$C$77,I8,$D$2:$D$77) -> 4.64 | L8: sábado | M8: =AVERAGEIF($C$2:$C$77,L8,$D$2:$D$77) -> 0.42181818
A9: Torre A Bupa | B9: 45952 | C9: =TEXT(B9,"dddd") -> miércoles | D9: 0.72 | E9: 0 | F9: 45952.333 | G9: 11 | I9: domingo | J9: =SUMIF($C$2:$C$77,I9,$D$2:$D$77) -> 3.76 | L9: domingo | M9: =AVERAGEIF($C$2:$C$77,L9,$D$2:$D$77) -> 0.34181818
A10: Torre A Bupa | B10: 45953 | C10: =TEXT(B10,"dddd") -> jueves | D10: 0.66 | E10: 0 | F10: 45953.458 | G10: 11
A11: Torre A Bupa | B11: 45954 | C11: =TEXT(B11,"dddd") -> viernes | D11: 1.53 | E11: 0 | I11: Consumo total | J11: =SUM($D$2:$D$77) -> 132.84
A12: Torre A Bupa | B12: 45955 | C12: =TEXT(B12,"dddd") -> sábado | D12: 1.13 | E12: 0 | F12: 45955.375 | G12: 11 | I12: Promedio driario | J12: =AVERAGE($D$2:$D$77) -> 1.7478947
A13: Torre A Bupa | B13: 45956 | C13: =TEXT(B13,"dddd") -> domingo | D13: 0.18 | E13: 0 | I13: MAX | J13: =MAX($D$2:$D$77) -> 28.35
A14: Torre A Bupa | B14: 45957 | C14: =TEXT(B14,"dddd") -> lunes | D14: 1.1 | E14: 0 | I14: MIN | J14: =MIN($D$2:$D$77) -> 0.09
A15: Torre A Bupa | B15: 45958 | C15: =TEXT(B15,"dddd") -> martes | D15: 0.41 | E15: 0 | F15: 45958.542 | G15: 11
A16: Torre A Bupa | B16: 45959 | C16: =TEXT(B16,"dddd") -> miércoles | D16: 0.42 | E16: 0 | F16: 45959.458 | G16: 11
A17: Torre A Bupa | B17: 45960 | C17: =TEXT(B17,"dddd") -> jueves | D17: 1.6 | E17: 0 | F17: 45960.708 | G17: 21
A18: Torre A Bupa | B18: 45961 | C18: =TEXT(B18,"dddd") -> viernes | D18: 0.21 | E18: 0 | F18: 45961.583 | G18: 11
A19: Torre A Bupa | B19: 45962 | C19: =TEXT(B19,"dddd") -> sábado | D19: 0.19 | E19: 0
A20: Torre A Bupa | B20: 45963 | C20: =TEXT(B20,"dddd") -> domingo | D20: 0.26 | E20: 0 | F20: 45963.5 | G20: 0.06
A21: Torre A Bupa | B21: 45964 | C21: =TEXT(B21,"dddd") -> lunes | D21: 0.54 | E21: 0 | F21: 45964.667 | G21: 111
A22: Torre A Bupa | B22: 45965 | C22: =TEXT(B22,"dddd") -> martes | D22: 15.1 | E22: 0
A23: Torre A Bupa | B23: 45966 | C23: =TEXT(B23,"dddd") -> miércoles | D23: 2.29 | E23: 0 | F23: 45966.875 | G23: 11
A24: Torre A Bupa | B24: 45967 | C24: =TEXT(B24,"dddd") -> jueves | D24: 2.63 | E24: 0
A25: Torre A Bupa | B25: 45968 | C25: =TEXT(B25,"dddd") -> viernes | D25: 0.3 | E25: 0 | F25: 45968.833 | G25: 11
A26: Torre A Bupa | B26: 45969 | C26: =TEXT(B26,"dddd") -> sábado | D26: 0.22 | E26: 0 | F26: 45969.667 | G26: 11
A27: Torre A Bupa | B27: 45970 | C27: =TEXT(B27,"dddd") -> domingo | D27: 0.22 | E27: 0
A28: Torre A Bupa | B28: 45971 | C28: =TEXT(B28,"dddd") -> lunes | D28: 0.98 | E28: 0 | F28: 45971.75 | G28: 41
A29: Torre A Bupa | B29: 45972 | C29: =TEXT(B29,"dddd") -> martes | D29: 1.06 | E29: 0 | F29: 45972.75 | G29: 11
A30: Torre A Bupa | B30: 45973 | C30: =TEXT(B30,"dddd") -> miércoles | D30: 0.38 | E30: 0 | F30: 45973.792 | G30: 11
A31: Torre A Bupa | B31: 45974 | C31: =TEXT(B31,"dddd") -> jueves | D31: 0.37 | E31: 0
A32: Torre A Bupa | B32: 45975 | C32: =TEXT(B32,"dddd") -> viernes | D32: 0.8 | E32: 0
A33: Torre A Bupa | B33: 45976 | C33: =TEXT(B33,"dddd") -> sábado | D33: 0.62 | E33: 0
A34: Torre A Bupa | B34: 45977 | C34: =TEXT(B34,"dddd") -> domingo | D34: 0.09 | E34: 0
A35: Torre A Bupa | B35: 45978 | C35: =TEXT(B35,"dddd") -> lunes | D35: 1.53 | E35: 0
A36: Torre A Bupa | B36: 45979 | C36: =TEXT(B36,"dddd") -> martes | D36: 0.93 | E36: 0 | F36: 45979.5 | G36: 31
A37: Torre A Bupa | B37: 45980 | C37: =TEXT(B37,"dddd") -> miércoles | D37: 15.09 | E37: 0
A38: Torre A Bupa | B38: 45981 | C38: =TEXT(B38,"dddd") -> jueves | D38: 0.9 | E38: 0 | F38: 45981.417 | G38: 11
A39: Torre A Bupa | B39: 45982 | C39: =TEXT(B39,"dddd") -> viernes | D39: 0.68 | E39: 0 | F39: 45982.75 | G39: 11
A40: Torre A Bupa | B40: 45983 | C40: =TEXT(B40,"dddd") -> sábado | D40: 0.52 | E40: 0 | F40: 45983.458 | G40: 21
...

Sheet Torre B1
A1: dispositivo | B1: fecha | C1: Dias | D1: m3 dia | E1: tarifa | F1: Fecha y Hora de alerta | G1: M3 Alerta
A2: Torre B1 Bupa | B2: 45945 | C2: =TEXT(B2,"dddd") -> miércoles | D2: 32 | E2: 0 | F2: 45945.875 | G2: 1001 | J2: TOTAL | M2: PROMEDIO
A3: Torre B1 Bupa | B3: 45946 | C3: =TEXT(B3,"dddd") -> jueves | D3: 27 | E3: 0 | F3: 45946.5 | G3: 1001 | I3: lunes | J3: =SUMIF($C$2:$C$77,I3,$D$2:$D$77) -> 563 | L3: lunes | M3: =AVERAGEIF($C$2:$C$77,L3,$D$2:$D$77) -> 51.181818
A4: Torre B1 Bupa | B4: 45947 | C4: =TEXT(B4,"dddd") -> viernes | D4: 31 | E4: 0 | F4: 45947.042 | G4: 1001 | I4: martes | J4: =SUMIF($C$2:$C$77,I4,$D$2:$D$77) -> 571 | L4: martes | M4: =AVERAGEIF($C$2:$C$77,L4,$D$2:$D$77) -> 57.1
A5: Torre B1 Bupa | B5: 45948 | C5: =TEXT(B5,"dddd") -> sábado | D5: 18 | E5: 0 | I5: miércoles | J5: =SUMIF($C$2:$C$77,I5,$D$2:$D$77) -> 710 | L5: miércoles | M5: =AVERAGEIF($C$2:$C$77,L5,$D$2:$D$77) -> 64.545455
A6: Torre B1 Bupa | B6: 45949 | C6: =TEXT(B6,"dddd") -> domingo | D6: 25 | E6: 0 | I6: jueves | J6: =SUMIF($C$2:$C$77,I6,$D$2:$D$77) -> 665 | L6: jueves | M6: =AVERAGEIF($C$2:$C$77,L6,$D$2:$D$77) -> 60.454545
A7: Torre B1 Bupa | B7: 45950 | C7: =TEXT(B7,"dddd") -> lunes | D7: 64 | E7: 0 | I7: viernes | J7: =SUMIF($C$2:$C$77,I7,$D$2:$D$77) -> 684 | L7: viernes | M7: =AVERAGEIF($C$2:$C$77,L7,$D$2:$D$77) -> 62.181818
A8: Torre B1 Bupa | B8: 45951 | C8: =TEXT(B8,"dddd") -> martes | D8: 20 | E8: 0 | F8: 45951.208 | G8: 1001 | I8: sábado | J8: =SUMIF($C$2:$C$77,I8,$D$2:$D$77) -> 499 | L8: sábado | M8: =AVERAGEIF($C$2:$C$77,L8,$D$2:$D$77) -> 45.363636
A9: Torre B1 Bupa | B9: 45952 | C9: =TEXT(B9,"dddd") -> miércoles | D9: 31 | E9: 0 | F9: 45952.875 | G9: 1001 | I9: domingo | J9: =SUMIF($C$2:$C$77,I9,$D$2:$D$77) -> 434 | L9: domingo | M9: =AVERAGEIF($C$2:$C$77,L9,$D$2:$D$77) -> 39.454545
A10: Torre B1 Bupa | B10: 45953 | C10: =TEXT(B10,"dddd") -> jueves | D10: 28 | E10: 0 | F10: 45953.5 | G10: 1001
A11: Torre B1 Bupa | B11: 45954 | C11: =TEXT(B11,"dddd") -> viernes | D11: 40 | E11: 0 | I11: Consumo total | J11: =SUM($D$2:$D$77) -> 4126
A12: Torre B1 Bupa | B12: 45955 | C12: =TEXT(B12,"dddd") -> sábado | D12: 15 | E12: 0 | F12: 45955.917 | G12: 1001 | I12: Promedio driario | J12: =AVERAGE($D$2:$D$77) -> 54.289474
A13: Torre B1 Bupa | B13: 45956 | C13: =TEXT(B13,"dddd") -> domingo | D13: 16 | E13: 0 | F13: 45956.792 | G13: 1001 | I13: MAX | J13: =MAX($D$2:$D$77) -> 119
A14: Torre B1 Bupa | B14: 45957 | C14: =TEXT(B14,"dddd") -> lunes | D14: 58 | E14: 0 | I14: MIN | J14: =MIN($D$2:$D$77) -> 15
A15: Torre B1 Bupa | B15: 45958 | C15: =TEXT(B15,"dddd") -> martes | D15: 21 | E15: 0 | F15: 45958.083 | G15: 1001
A16: Torre B1 Bupa | B16: 45959 | C16: =TEXT(B16,"dddd") -> miércoles | D16: 60 | E16: 0 | F16: 45959.458 | G16: 1001
A17: Torre B1 Bupa | B17: 45960 | C17: =TEXT(B17,"dddd") -> jueves | D17: 59 | E17: 0
A18: Torre B1 Bupa | B18: 45961 | C18: =TEXT(B18,"dddd") -> viernes | D18: 24 | E18: 0 | F18: 45961.208 | G18: 1001
A19: Torre B1 Bupa | B19: 45962 | C19: =TEXT(B19,"dddd") -> sábado | D19: 40 | E19: 0 | F19: 45962.167 | G19: 1001
A20: Torre B1 Bupa | B20: 45963 | C20: =TEXT(B20,"dddd") -> domingo | D20: 30 | E20: 0
A21: Torre B1 Bupa | B21: 45964 | C21: =TEXT(B21,"dddd") -> lunes | D21: 35 | E21: 0 | F21: 45964.375 | G21: 1001
A22: Torre B1 Bupa | B22: 45965 | C22: =TEXT(B22,"dddd") -> martes | D22: 40 | E22: 0
A23: Torre B1 Bupa | B23: 45966 | C23: =TEXT(B23,"dddd") -> miércoles | D23: 80 | E23: 0 | F23: 45966.208 | G23: 1001
A24: Torre B1 Bupa | B24: 45967 | C24: =TEXT(B24,"dddd") -> jueves | D24: 39 | E24: 0 | F24: 45967.417 | G24: 1001
A25: Torre B1 Bupa | B25: 45968 | C25: =TEXT(B25,"dddd") -> viernes | D25: 99 | E25: 0
A26: Torre B1 Bupa | B26: 45969 | C26: =TEXT(B26,"dddd") -> sábado | D26: 26 | E26: 0 | F26: 45969.417 | G26: 1001
A27: Torre B1 Bupa | B27: 45970 | C27: =TEXT(B27,"dddd") -> domingo | D27: 25 | E27: 0 | F27: 45970.75 | G27: 1001
A28: Torre B1 Bupa | B28: 45971 | C28: =TEXT(B28,"dddd") -> lunes | D28: 48 | E28: 0 | F28: 45971.333 | G28: 1001
A29: Torre B1 Bupa | B29: 45972 | C29: =TEXT(B29,"dddd") -> martes | D29: 48 | E29: 0 | F29: 45972.417 | G29: 1001
A30: Torre B1 Bupa | B30: 45973 | C30: =TEXT(B30,"dddd") -> miércoles | D30: 59 | E30: 0
A31: Torre B1 Bupa | B31: 45974 | C31: =TEXT(B31,"dddd") -> jueves | D31: 55 | E31: 0 | F31: 45974.167 | G31: 1001
A32: Torre B1 Bupa | B32: 45975 | C32: =TEXT(B32,"dddd") -> viernes | D32: 38 | E32: 0
A33: Torre B1 Bupa | B33: 45976 | C33: =TEXT(B33,"dddd") -> sábado | D33: 42 | E33: 0
A34: Torre B1 Bupa | B34: 45977 | C34: =TEXT(B34,"dddd") -> domingo | D34: 71 | E34: 0 | F34: 45977.958 | G34: 1001
A35: Torre B1 Bupa | B35: 45978 | C35: =TEXT(B35,"dddd") -> lunes | D35: 26 | E35: 0 | F35: 45978.5 | G35: 1001
A36: Torre B1 Bupa | B36: 45979 | C36: =TEXT(B36,"dddd") -> martes | D36: 65 | E36: 0 | F36: 45979.833 | G36: 1001
A37: Torre B1 Bupa | B37: 45980 | C37: =TEXT(B37,"dddd") -> miércoles | D37: 59 | E37: 0 | F37: 45980.375 | G37: 1001
A38: Torre B1 Bupa | B38: 45981 | C38: =TEXT(B38,"dddd") -> jueves | D38: 58 | E38: 0 | F38: 45981.458 | G38: 1001
A39: Torre B1 Bupa | B39: 45982 | C39: =TEXT(B39,"dddd") -> viernes | D39: 38 | E39: 0
A40: Torre B1 Bupa | B40: 45983 | C40: =TEXT(B40,"dddd") -> sábado | D40: 37 | E40: 0 | F40: 45983.208 | G40: 1001
...

Sheet Torre B2
A1: dispositivo | B1: fecha | C1: Dias | D1: m3 dia | E1: tarifa | F1: Fecha y Hora de alerta | G1: M3 Alerta
A2: Torre B2 Bupa | B2: 45945 | C2: =TEXT(B2,"dddd") -> miércoles | D2: 89.96 | E2: 0 | J2: TOTAL | M2: PROMEDIO
A3: Torre B2 Bupa | B3: 45946 | C3: =TEXT(B3,"dddd") -> jueves | D3: 84.73 | E3: 0 | I3: lunes | J3: =SUMIF($C$2:$C$77,I3,$D$2:$D$77) -> 1131.39 | L3: lunes | M3: =AVERAGEIF($C$2:$C$77,L3,$D$2:$D$77) -> 102.85364
A4: Torre B2 Bupa | B4: 45947 | C4: =TEXT(B4,"dddd") -> viernes | D4: 102.66 | E4: 0 | I4: martes | J4: =SUMIF($C$2:$C$77,I4,$D$2:$D$77) -> 995.38 | L4: martes | M4: =AVERAGEIF($C$2:$C$77,L4,$D$2:$D$77) -> 99.538
A5: Torre B2 Bupa | B5: 45948 | C5: =TEXT(B5,"dddd") -> sábado | D5: 96.04 | E5: 0 | I5: miércoles | J5: =SUMIF($C$2:$C$77,I5,$D$2:$D$77) -> 1021.62 | L5: miércoles | M5: =AVERAGEIF($C$2:$C$77,L5,$D$2:$D$77) -> 92.874545
A6: Torre B2 Bupa | B6: 45949 | C6: =TEXT(B6,"dddd") -> domingo | D6: 88.31 | E6: 0 | I6: jueves | J6: =SUMIF($C$2:$C$77,I6,$D$2:$D$77) -> 1072.35 | L6: jueves | M6: =AVERAGEIF($C$2:$C$77,L6,$D$2:$D$77) -> 97.486364
A7: Torre B2 Bupa | B7: 45950 | C7: =TEXT(B7,"dddd") -> lunes | D7: 94.09 | E7: 0 | I7: viernes | J7: =SUMIF($C$2:$C$77,I7,$D$2:$D$77) -> 1092.09 | L7: viernes | M7: =AVERAGEIF($C$2:$C$77,L7,$D$2:$D$77) -> 99.280909
A8: Torre B2 Bupa | B8: 45951 | C8: =TEXT(B8,"dddd") -> martes | D8: 108.58 | E8: 0 | I8: sábado | J8: =SUMIF($C$2:$C$77,I8,$D$2:$D$77) -> 925.08 | L8: sábado | M8: =AVERAGEIF($C$2:$C$77,L8,$D$2:$D$77) -> 84.098182
A9: Torre B2 Bupa | B9: 45952 | C9: =TEXT(B9,"dddd") -> miércoles | D9: 97.57 | E9: 0 | I9: domingo | J9: =SUMIF($C$2:$C$77,I9,$D$2:$D$77) -> 918.72 | L9: domingo | M9: =AVERAGEIF($C$2:$C$77,L9,$D$2:$D$77) -> 83.52
A10: Torre B2 Bupa | B10: 45953 | C10: =TEXT(B10,"dddd") -> jueves | D10: 77.06 | E10: 0
A11: Torre B2 Bupa | B11: 45954 | C11: =TEXT(B11,"dddd") -> viernes | D11: 82.49 | E11: 0 | I11: Consumo total | J11: =SUM($D$2:$D$77) -> 7156.63
A12: Torre B2 Bupa | B12: 45955 | C12: =TEXT(B12,"dddd") -> sábado | D12: 88.94 | E12: 0 | I12: Promedio driario | J12: =AVERAGE($D$2:$D$77) -> 94.166184
A13: Torre B2 Bupa | B13: 45956 | C13: =TEXT(B13,"dddd") -> domingo | D13: 73.78 | E13: 0 | F13: 45956.208 | G13: 121 | I13: MAX | J13: =MAX($D$2:$D$77) -> 154.91
A14: Torre B2 Bupa | B14: 45957 | C14: =TEXT(B14,"dddd") -> lunes | D14: 84.85 | E14: 0 | I14: MIN | J14: =MIN($D$2:$D$77) -> 62.64
A15: Torre B2 Bupa | B15: 45958 | C15: =TEXT(B15,"dddd") -> martes | D15: 91.48 | E15: 0
A16: Torre B2 Bupa | B16: 45959 | C16: =TEXT(B16,"dddd") -> miércoles | D16: 91.14 | E16: 0
A17: Torre B2 Bupa | B17: 45960 | C17: =TEXT(B17,"dddd") -> jueves | D17: 88.01 | E17: 0
A18: Torre B2 Bupa | B18: 45961 | C18: =TEXT(B18,"dddd") -> viernes | D18: 75.11 | E18: 0
A19: Torre B2 Bupa | B19: 45962 | C19: =TEXT(B19,"dddd") -> sábado | D19: 75.13 | E19: 0
A20: Torre B2 Bupa | B20: 45963 | C20: =TEXT(B20,"dddd") -> domingo | D20: 97.76 | E20: 0
A21: Torre B2 Bupa | B21: 45964 | C21: =TEXT(B21,"dddd") -> lunes | D21: 82.53 | E21: 0
A22: Torre B2 Bupa | B22: 45965 | C22: =TEXT(B22,"dddd") -> martes | D22: 87.71 | E22: 0
A23: Torre B2 Bupa | B23: 45966 | C23: =TEXT(B23,"dddd") -> miércoles | D23: 82.55 | E23: 0
A24: Torre B2 Bupa | B24: 45967 | C24: =TEXT(B24,"dddd") -> jueves | D24: 64.4 | E24: 0
A25: Torre B2 Bupa | B25: 45968 | C25: =TEXT(B25,"dddd") -> viernes | D25: 74.64 | E25: 0
A26: Torre B2 Bupa | B26: 45969 | C26: =TEXT(B26,"dddd") -> sábado | D26: 64.72 | E26: 0
A27: Torre B2 Bupa | B27: 45970 | C27: =TEXT(B27,"dddd") -> domingo | D27: 64.12 | E27: 0
A28: Torre B2 Bupa | B28: 45971 | C28: =TEXT(B28,"dddd") -> lunes | D28: 74.76 | E28: 0 | F28: 45971.125 | G28: 91
A29: Torre B2 Bupa | B29: 45972 | C29: =TEXT(B29,"dddd") -> martes | D29: 79.37 | E29: 0
A30: Torre B2 Bupa | B30: 45973 | C30: =TEXT(B30,"dddd") -> miércoles | D30: 88.11 | E30: 0
A31: Torre B2 Bupa | B31: 45974 | C31: =TEXT(B31,"dddd") -> jueves | D31: 86.91 | E31: 0
A32: Torre B2 Bupa | B32: 45975 | C32: =TEXT(B32,"dddd") -> viernes | D32: 94.66 | E32: 0
A33: Torre B2 Bupa | B33: 45976 | C33: =TEXT(B33,"dddd") -> sábado | D33: 67.97 | E33: 0
A34: Torre B2 Bupa | B34: 45977 | C34: =TEXT(B34,"dddd") -> domingo | D34: 65.24 | E34: 0
A35: Torre B2 Bupa | B35: 45978 | C35: =TEXT(B35,"dddd") -> lunes | D35: 103.03 | E35: 0
A36: Torre B2 Bupa | B36: 45979 | C36: =TEXT(B36,"dddd") -> martes | D36: 108.65 | E36: 0
A37: Torre B2 Bupa | B37: 45980 | C37: =TEXT(B37,"dddd") -> miércoles | D37: 123.94 | E37: 0
A38: Torre B2 Bupa | B38: 45981 | C38: =TEXT(B38,"dddd") -> jueves | D38: 95.93 | E38: 0
A39: Torre B2 Bupa | B39: 45982 | C39: =TEXT(B39,"dddd") -> viernes | D39: 98.33 | E39: 0
A40: Torre B2 Bupa | B40: 45983 | C40: =TEXT(B40,"dddd") -> sábado | D40: 86.9 | E40: 0
...

Sheet Torre C
A1: dispositivo | B1: fecha | C1: Dias | D1: m3 dia | E1: tarifa | F1: Fecha y Hora de alerta | G1: M3 Alerta
A2: Torre C Bupa | B2: 45945 | C2: =TEXT(B2,"dddd") -> miércoles | D2: 3.19 | E2: 0 | J2: TOTAL | M2: PROMEDIO
A3: Torre C Bupa | B3: 45946 | C3: =TEXT(B3,"dddd") -> jueves | D3: 2.57 | E3: 0 | F3: 45946.833 | G3: 11 | I3: lunes | J3: =SUMIF($C$2:$C$77,I3,$D$2:$D$77) -> 42.88 | L3: lunes | M3: =AVERAGEIF($C$2:$C$77,L3,$D$2:$D$77) -> 3.8981818
A4: Torre C Bupa | B4: 45947 | C4: =TEXT(B4,"dddd") -> viernes | D4: 4.08 | E4: 0 | I4: martes | J4: =SUMIF($C$2:$C$77,I4,$D$2:$D$77) -> 38.95 | L4: martes | M4: =AVERAGEIF($C$2:$C$77,L4,$D$2:$D$77) -> 3.895
A5: Torre C Bupa | B5: 45948 | C5: =TEXT(B5,"dddd") -> sábado | D5: 0.39 | E5: 0 | F5: 45948.792 | G5: 11 | I5: miércoles | J5: =SUMIF($C$2:$C$77,I5,$D$2:$D$77) -> 36.85 | L5: miércoles | M5: =AVERAGEIF($C$2:$C$77,L5,$D$2:$D$77) -> 3.35
A6: Torre C Bupa | B6: 45949 | C6: =TEXT(B6,"dddd") -> domingo | D6: 0.01 | E6: 0 | I6: jueves | J6: =SUMIF($C$2:$C$77,I6,$D$2:$D$77) -> 34.13 | L6: jueves | M6: =AVERAGEIF($C$2:$C$77,L6,$D$2:$D$77) -> 3.1027273
A7: Torre C Bupa | B7: 45950 | C7: =TEXT(B7,"dddd") -> lunes | D7: 4.46 | E7: 0 | I7: viernes | J7: =SUMIF($C$2:$C$77,I7,$D$2:$D$77) -> 25.85 | L7: viernes | M7: =AVERAGEIF($C$2:$C$77,L7,$D$2:$D$77) -> 2.35
A8: Torre C Bupa | B8: 45951 | C8: =TEXT(B8,"dddd") -> martes | D8: 3.58 | E8: 0 | I8: sábado | J8: =SUMIF($C$2:$C$77,I8,$D$2:$D$77) -> 3.65 | L8: sábado | M8: =AVERAGEIF($C$2:$C$77,L8,$D$2:$D$77) -> 0.33181818
A9: Torre C Bupa | B9: 45952 | C9: =TEXT(B9,"dddd") -> miércoles | D9: 3.86 | E9: 0 | I9: domingo | J9: =SUMIF($C$2:$C$77,I9,$D$2:$D$77) -> 0.22 | L9: domingo | M9: =AVERAGEIF($C$2:$C$77,L9,$D$2:$D$77) -> 0.02
A10: Torre C Bupa | B10: 45953 | C10: =TEXT(B10,"dddd") -> jueves | D10: 3.22 | E10: 0
A11: Torre C Bupa | B11: 45954 | C11: =TEXT(B11,"dddd") -> viernes | D11: 4.6 | E11: 0 | I11: Consumo total | J11: =SUM($D$2:$D$77) -> 182.53
A12: Torre C Bupa | B12: 45955 | C12: =TEXT(B12,"dddd") -> sábado | D12: 0.63 | E12: 0 | F12: 45955.542 | G12: 41 | I12: Promedio driario | J12: =AVERAGE($D$2:$D$77) -> 2.4017105
A13: Torre C Bupa | B13: 45956 | C13: =TEXT(B13,"dddd") -> domingo | D13: 0.14 | E13: 0 | F13: 45956.458 | G13: 21 | I13: MAX | J13: =MAX($D$2:$D$77) -> 6.29
A14: Torre C Bupa | B14: 45957 | C14: =TEXT(B14,"dddd") -> lunes | D14: 4.35 | E14: 0 | I14: MIN | J14: =MIN($D$2:$D$77) -> 0
A15: Torre C Bupa | B15: 45958 | C15: =TEXT(B15,"dddd") -> martes | D15: 5.3 | E15: 0
A16: Torre C Bupa | B16: 45959 | C16: =TEXT(B16,"dddd") -> miércoles | D16: 3.8 | E16: 0
A17: Torre C Bupa | B17: 45960 | C17: =TEXT(B17,"dddd") -> jueves | D17: 2.68 | E17: 0 | F17: 45960.833 | G17: 11
A18: Torre C Bupa | B18: 45961 | C18: =TEXT(B18,"dddd") -> viernes | D18: 0.23 | E18: 0 | F18: 45961.917 | G18: 21
A19: Torre C Bupa | B19: 45962 | C19: =TEXT(B19,"dddd") -> sábado | D19: 0.29 | E19: 0 | F19: 45962.333 | G19: 11
A20: Torre C Bupa | B20: 45963 | C20: =TEXT(B20,"dddd") -> domingo | D20: 0.01 | E20: 0
A21: Torre C Bupa | B21: 45964 | C21: =TEXT(B21,"dddd") -> lunes | D21: 5.73 | E21: 0
A22: Torre C Bupa | B22: 45965 | C22: =TEXT(B22,"dddd") -> martes | D22: 4.08 | E22: 0
A23: Torre C Bupa | B23: 45966 | C23: =TEXT(B23,"dddd") -> miércoles | D23: 6.29 | E23: 0
A24: Torre C Bupa | B24: 45967 | C24: =TEXT(B24,"dddd") -> jueves | D24: 3.75 | E24: 0
A25: Torre C Bupa | B25: 45968 | C25: =TEXT(B25,"dddd") -> viernes | D25: 2.03 | E25: 0 | F25: 45968.417 | G25: 51
A26: Torre C Bupa | B26: 45969 | C26: =TEXT(B26,"dddd") -> sábado | D26: 0.14 | E26: 0 | F26: 45969.625 | G26: 11
A27: Torre C Bupa | B27: 45970 | C27: =TEXT(B27,"dddd") -> domingo | D27: 0 | E27: 0
A28: Torre C Bupa | B28: 45971 | C28: =TEXT(B28,"dddd") -> lunes | D28: 4.8 | E28: 0
A29: Torre C Bupa | B29: 45972 | C29: =TEXT(B29,"dddd") -> martes | D29: 4.2 | E29: 0
A30: Torre C Bupa | B30: 45973 | C30: =TEXT(B30,"dddd") -> miércoles | D30: 4.48 | E30: 0
A31: Torre C Bupa | B31: 45974 | C31: =TEXT(B31,"dddd") -> jueves | D31: 4.13 | E31: 0
A32: Torre C Bupa | B32: 45975 | C32: =TEXT(B32,"dddd") -> viernes | D32: 2.41 | E32: 0
A33: Torre C Bupa | B33: 45976 | C33: =TEXT(B33,"dddd") -> sábado | D33: 0.22 | E33: 0
A34: Torre C Bupa | B34: 45977 | C34: =TEXT(B34,"dddd") -> domingo | D34: 0 | E34: 0
A35: Torre C Bupa | B35: 45978 | C35: =TEXT(B35,"dddd") -> lunes | D35: 4.95 | E35: 0 | F35: 45978.417 | G35: 21
A36: Torre C Bupa | B36: 45979 | C36: =TEXT(B36,"dddd") -> martes | D36: 4.37 | E36: 0
A37: Torre C Bupa | B37: 45980 | C37: =TEXT(B37,"dddd") -> miércoles | D37: 2.47 | E37: 0
A38: Torre C Bupa | B38: 45981 | C38: =TEXT(B38,"dddd") -> jueves | D38: 3.6 | E38: 0
A39: Torre C Bupa | B39: 45982 | C39: =TEXT(B39,"dddd") -> viernes | D39: 2.39 | E39: 0 | F39: 45982.417 | G39: 0.06
A40: Torre C Bupa | B40: 45983 | C40: =TEXT(B40,"dddd") -> sábado | D40: 0.22 | E40: 0 | F40: 45983.583 | G40: 11
...

Sheet Central Termica
A1: dispositivo | B1: fecha | C1: Dias | D1: m3 dia | E1: tarifa | F1: Fecha y Hora de alerta | G1: M3 Alerta
A2: Central Térmica Bupa | B2: 45945 | C2: =TEXT(B2,"dddd") -> miércoles | D2: 51.98 | E2: 0 | J2: TOTAL | M2: PROMEDIO
A3: Central Térmica Bupa | B3: 45946 | C3: =TEXT(B3,"dddd") -> jueves | D3: 51.07 | E3: 0 | I3: lunes | J3: =SUMIF($C$2:$C$77,I3,$D$2:$D$77) -> 564.08 | L3: lunes | M3: =AVERAGEIF($C$2:$C$77,L3,$D$2:$D$77) -> 51.28
A4: Central Térmica Bupa | B4: 45947 | C4: =TEXT(B4,"dddd") -> viernes | D4: 58.79 | E4: 0 | I4: martes | J4: =SUMIF($C$2:$C$77,I4,$D$2:$D$77) -> 537.42 | L4: martes | M4: =AVERAGEIF($C$2:$C$77,L4,$D$2:$D$77) -> 53.742
A5: Central Térmica Bupa | B5: 45948 | C5: =TEXT(B5,"dddd") -> sábado | D5: 48.01 | E5: 0 | I5: miércoles | J5: =SUMIF($C$2:$C$77,I5,$D$2:$D$77) -> 549.75 | L5: miércoles | M5: =AVERAGEIF($C$2:$C$77,L5,$D$2:$D$77) -> 49.977273
A6: Central Térmica Bupa | B6: 45949 | C6: =TEXT(B6,"dddd") -> domingo | D6: 38.22 | E6: 0 | I6: jueves | J6: =SUMIF($C$2:$C$77,I6,$D$2:$D$77) -> 604.94 | L6: jueves | M6: =AVERAGEIF($C$2:$C$77,L6,$D$2:$D$77) -> 54.994545
A7: Central Térmica Bupa | B7: 45950 | C7: =TEXT(B7,"dddd") -> lunes | D7: 55.63 | E7: 0 | I7: viernes | J7: =SUMIF($C$2:$C$77,I7,$D$2:$D$77) -> 561.81 | L7: viernes | M7: =AVERAGEIF($C$2:$C$77,L7,$D$2:$D$77) -> 51.073636
A8: Central Térmica Bupa | B8: 45951 | C8: =TEXT(B8,"dddd") -> martes | D8: 56.63 | E8: 0 | I8: sábado | J8: =SUMIF($C$2:$C$77,I8,$D$2:$D$77) -> 478.05 | L8: sábado | M8: =AVERAGEIF($C$2:$C$77,L8,$D$2:$D$77) -> 43.459091
A9: Central Térmica Bupa | B9: 45952 | C9: =TEXT(B9,"dddd") -> miércoles | D9: 56.43 | E9: 0 | I9: domingo | J9: =SUMIF($C$2:$C$77,I9,$D$2:$D$77) -> 454.9 | L9: domingo | M9: =AVERAGEIF($C$2:$C$77,L9,$D$2:$D$77) -> 41.354545
A10: Central Térmica Bupa | B10: 45953 | C10: =TEXT(B10,"dddd") -> jueves | D10: 55.11 | E10: 0
A11: Central Térmica Bupa | B11: 45954 | C11: =TEXT(B11,"dddd") -> viernes | D11: 53.61 | E11: 0 | I11: Consumo total | J11: =SUM($D$2:$D$77) -> 3750.95
A12: Central Térmica Bupa | B12: 45955 | C12: =TEXT(B12,"dddd") -> sábado | D12: 50.19 | E12: 0 | I12: Promedio driario | J12: =AVERAGE($D$2:$D$77) -> 49.354605
A13: Central Térmica Bupa | B13: 45956 | C13: =TEXT(B13,"dddd") -> domingo | D13: 42.07 | E13: 0 | I13: MAX | J13: =MAX($D$2:$D$77) -> 72.37
A14: Central Térmica Bupa | B14: 45957 | C14: =TEXT(B14,"dddd") -> lunes | D14: 51.67 | E14: 0 | I14: MIN | J14: =MIN($D$2:$D$77) -> 30.21
A15: Central Térmica Bupa | B15: 45958 | C15: =TEXT(B15,"dddd") -> martes | D15: 57.74 | E15: 0
A16: Central Térmica Bupa | B16: 45959 | C16: =TEXT(B16,"dddd") -> miércoles | D16: 56.81 | E16: 0
A17: Central Térmica Bupa | B17: 45960 | C17: =TEXT(B17,"dddd") -> jueves | D17: 60.14 | E17: 0
A18: Central Térmica Bupa | B18: 45961 | C18: =TEXT(B18,"dddd") -> viernes | D18: 48.86 | E18: 0
A19: Central Térmica Bupa | B19: 45962 | C19: =TEXT(B19,"dddd") -> sábado | D19: 44.21 | E19: 0
A20: Central Térmica Bupa | B20: 45963 | C20: =TEXT(B20,"dddd") -> domingo | D20: 37.95 | E20: 0
A21: Central Térmica Bupa | B21: 45964 | C21: =TEXT(B21,"dddd") -> lunes | D21: 51.33 | E21: 0
A22: Central Térmica Bupa | B22: 45965 | C22: =TEXT(B22,"dddd") -> martes | D22: 58.46 | E22: 0
A23: Central Térmica Bupa | B23: 45966 | C23: =TEXT(B23,"dddd") -> miércoles | D23: 51.45 | E23: 0
A24: Central Térmica Bupa | B24: 45967 | C24: =TEXT(B24,"dddd") -> jueves | D24: 54.95 | E24: 0
A25: Central Térmica Bupa | B25: 45968 | C25: =TEXT(B25,"dddd") -> viernes | D25: 57.11 | E25: 0
A26: Central Térmica Bupa | B26: 45969 | C26: =TEXT(B26,"dddd") -> sábado | D26: 42.58 | E26: 0
... A62: Central Térmica Bupa | B62: 46005 | C62: =TEXT(B62,"dddd") -> domingo | D62: 36.39 | E62: 0
A63: Central Térmica Bupa | B63: 46006 | C63: =TEXT(B63,"dddd") -> lunes | D63: 59.65 | E63: 0 | F63: 46006.25 | G63: 801
A64: Central Térmica Bupa | B64: 46007 | C64: =TEXT(B64,"dddd") -> martes | D64: 47.81 | E64: 0
A65: Central Térmica Bupa | B65: 46008 | C65: =TEXT(B65,"dddd") -> miércoles | D65: 41.93 | E65: 0
A66: Central Térmica Bupa | B66: 46009 | C66: =TEXT(B66,"dddd") -> jueves | D66: 56.38 | E66: 0
A67: Central Térmica Bupa | B67: 46010 | C67: =TEXT(B67,"dddd") -> viernes | D67: 44.73 | E67: 0
A68: Central Térmica Bupa | B68: 46011 | C68: =TEXT(B68,"dddd") -> sábado | D68: 37.96 | E68: 0
A69: Central Térmica Bupa | B69: 46012 | C69: =TEXT(B69,"dddd") -> domingo | D69: 39.38 | E69: 0
A70: Central Térmica Bupa | B70: 46013 | C70: =TEXT(B70,"dddd") -> lunes | D70: 48.5 | E70: 0 | F70: 46013.042 | G70: 1.181
A71: Central Térmica Bupa | B71: 46014 | C71: =TEXT(B71,"dddd") -> martes | D71: 46.18 | E71: 0
A72: Central Térmica Bupa | B72: 46015 | C72: =TEXT(B72,"dddd") -> miércoles | D72: 40.32 | E72: 0
A73: Central Térmica Bupa | B73: 46016 | C73: =TEXT(B73,"dddd") -> jueves | D73: 37.22 | E73: 0
A74: Central Térmica Bupa | B74: 46017 | C74: =TEXT(B74,"dddd") -> viernes | D74: 31.65
A75: Central Térmica Bupa | B75: 46018 | C75: =TEXT(B75,"dddd") -> sábado | D75: 32.41
...

Sheet Agragado
A2: Ranking | B2: Dispositivo | C2: Consumo total (m³) | D2: Promedio diario (m³)
A3: 1 | B3: Llenado de Estanques | C3: =Estanques!J12 -> 26137.43 | D3: =Estanques!J13 -> 343.91355
A4: 2 | B4: Torre B2 | C4: ='Torre B2'!J11 -> 7156.63 | D4: ='Torre B2'!J12 -> 94.166184
A5: 3 | B5: Torre B1 | C5: ='Torre B1'!J11 -> 4126 | D5: ='Torre B1'!J12 -> 54.289474
A6: 4 | B6: Central Térmica | C6: ='Central Termica'!J11 -> 3750.95 | D6: 50,3
A7: 5 | B7: Torre C | C7: ='Torre C'!J11 -> 182.53 | D7: ='Torre C'!J12 -> 2.4017105
A8: 6 | B8: Torre A | C8: ='Torre A'!J11 -> 132.84 | D8: ='Torre A'!J12 -> 1.7478947

Sheet Boleta
A1: Mes/Año | B1: Fecha de lectura | C1: Consumo propio (m3) | D1: Consumo prorrateado (m3) | E1: Consumo total (m3) | F1: Límite de sobreconsumo (m3) | G1: Total sobreconsumo (m3) | H1: Observación
A2: 44927 | B2: 44931 | C2: 8122 | D2: 0 | E2: 8122 | F2: 7268 | G2: 854 | H2: LECTURA NORMAL
A3: 44958 | B3: 44960 | C3: 9162 | D3: 0 | E3: 9162 | F3: 7268 | G3: 1894 | H3: LECTURA NORMAL | L3: Consumo total (m3)
A4: 44986 | B4: 44991 | C4: 11237 | D4: 0 | E4: 11237 | F4: 7268 | G4: 3969 | H4: LECTURA NORMAL | K4: 44927 | L4: 8122 | N4: suma total | O4: =SUM(L4:L39) -> 320613 | Q4: 44927 | R4: 8122 | S4: I semestre 2023 | T4: =SUM(R4:R9) -> 56149
A5: 45017 | B5: 45021 | C5: 8883 | D5: 0 | E5: 8883 | F5: 7268 | G5: 1345 | H5: LECTURA NORMAL | K5: 44958 | L5: 9162 | N5: promedio mes | O5: =AVERAGE(L4:L39) -> 8905.9167 | Q5: 44958 | R5: 9162 | S5: II semestre 2023 | T5: =SUM(R11:R16) -> 53064
A6: 45047 | B6: 45051 | C6: 9530 | D6: 0 | E6: 9530 | F6: 0 | G6: 0 | H6: LECTURA NORMAL | K6: 44986 | L6: 11237 | Q6: 44986 | R6: 11237 | S6: I semestre 2024 | T6: =SUM(R18:R23) -> 60328
A7: 45078 | B7: 45082 | C7: 9215 | D7: 0 | E7: 9215 | F7: 0 | G7: 0 | H7: LECTURA NORMAL | K7: 45017 | L7: 8883 | N7: min | O7: =MIN(L4:L39) -> 6570 | Q7: 45017 | R7: 8883 | S7: II semestre 2024 | T7: =SUM(R25:R31) -> 51395
A8: 45108 | B8: 45112 | C8: 8553 | D8: 0 | E8: 8553 | F8: 0 | G8: 0 | H8: LECTURA NORMAL | K8: 45047 | L8: 9530 | N8: max | O8: =MAX(L4:L39) -> 13113 | Q8: 45047 | R8: 9530 | S8: I semestre 2025 | T8: =SUM(R33:R38) -> 52688
A9: 45139 | B9: 45142 | C9: 8187 | D9: 0 | E9: 8187 | F9: 0 | G9: 0 | H9: LECTURA NORMAL | K9: 45078 | L9: 9215 | Q9: 45078 | R9: 9215 | S9: II semestre 2025 | T9: =SUM(R40:R45) -> 53559
A10: 45170 | B10: 45174 | C10: 9242 | D10: 0 | E10: 9242 | F10: 0 | G10: 0 | H10: LECTURA NORMAL | K10: 45108 | L10: 8553
A11: 45200 | B11: 45203 | C11: 9539 | D11: 0 | E11: 9539 | F11: 0 | G11: 0 | H11: LECTURA NORMAL | K11: 45139 | L11: 8187 | Q11: 45108 | R11: 8553
A12: 45231 | B12: 45234 | C12: 9309 | D12: 0 | E12: 9309 | F12: 0 | G12: 0 | H12: LECTURA NORMAL | K12: 45170 | L12: 9242 | N12: 2023 | Q12: 45139 | R12: 8187
A13: 45261 | B13: 45265 | C13: 8234 | D13: 0 | E13: 8234 | F13: 9058 | G13: 0 | H13: LECTURA NORMAL | K13: 45200 | L13: 9539 | N13: promedio | O13: =AVERAGE(L4:L15) -> 9101.0833 | Q13: 45170 | R13: 9242
A14: 45292 | B14: 45295 | C14: 9486 | D14: 0 | E14: 9486 | F14: 9058 | G14: 428 | H14: LECTURA NORMAL | K14: 45231 | L14: 9309 | Q14: 45200 | R14: 9539
A15: 45323 | B15: 45327 | C15: 13113 | D15: 0 | E15: 13113 | F15: 9058 | G15: 4055 | H15: LECTURA NORMAL | K15: 45261 | L15: 8234 | Q15: 45231 | R15: 9309
A16: 45352 | B16: 45356 | C16: 12326 | D16: 0 | E16: 12326 | F16: 9058 | G16: 3268 | H16: LECTURA NORMAL | K16: 45292 | L16: 9486 | N16: 2024 | Q16: 45261 | R16: 8234
A17: 45383 | B17: 45386 | C17: 9822 | D17: 0 | E17: 9822 | F17: 9058 | G17: 662 | H17: LECTURA NORMAL | K17: 45323 | L17: 13113 | N17: promedio | O17: =AVERAGE(L16:L27) -> 8762.75
A18: 45413 | B18: 45418 | C18: 9011 | D18: 0 | E18: 9011 | F18: 0 | G18: 0 | H18: LECTURA NORMAL | K18: 45352 | L18: 12326 | Q18: 45292 | R18: 9486
A19: 45444 | B19: 45448 | C19: 6570 | D19: 0 | E19: 6570 | F19: 0 | G19: 0 | H19: LECTURA NORMAL | K19: 45383 | L19: 9822 | Q19: 45323 | R19: 13113
A20: 45474 | B20: 45479 | C20: 6867 | D20: 0 | E20: 6867 | F20: 0 | G20: 0 | H20: LECTURA NORMAL | K20: 45413 | L20: 9011 | N20: 2025 | Q20: 45352 | R20: 12326
A21: 45505 | B21: 45509 | C21: 6719 | D21: 0 | E21: 6719 | F21: 0 | G21: 0 | H21: LECTURA NORMAL | K21: 45444 | L21: 6570 | N21: promedio | O21: =AVERAGE(L28:L39) -> 8853.9167 | Q21: 45383 | R21: 9822
A22: 45536 | B22: 45539 | C22: 7191 | D22: 0 | E22: 7191 | F22: 0 | G22: 0 | H22: LECTURA NORMAL | K22: 45474 | L22: 6867 | Q22: 45413 | R22: 9011
A23: 45566 | B23: 45569 | C23: 7831 | D23: 0 | E23: 7831 | F23: 0 | G23: 0 | H23: LECTURA NORMAL | K23: 45505 | L23: 6719 | N23: =SUM(L28:L39) -> 106247 | Q23: 45444 | R23: 6570
A24: 45597 | B24: 45601 | C24: 8645 | D24: 0 | E24: 8645 | F24: 0 | G24: 0 | H24: LECTURA NORMAL | K24: 45536 | L24: 7191
A25: 45627 | B25: 45631 | C25: 7572 | D25: 0 | E25: 7572 | F25: 7832 | G25: 0 | H25: LECTURA NORMAL | K25: 45566 | L25: 7831 | Q25: 45444 | R25: 6570
A26: 45658 | B26: 45661 | C26: 9223 | D26: 0 | E26: 9223 | F26: 7832 | G26: 1391 | H26: LECTURA NORMAL | K26: 45597 | L26: 8645 | Q26: 45474 | R26: 6867
A27: 45689 | B27: 45693 | C27: 10356 | D27: 0 | E27: 10356 | F27: 7832 | G27: 2524 | H27: LECTURA NORMAL | K27: 45627 | L27: 7572 | Q27: 45505 | R27: 6719
A28: 45717 | B28: 45723 | C28: 9117 | D28: 0 | E28: 9117 | F28: 7832 | G28: 1285 | H28: LECTURA NORMAL | K28: 45658 | L28: 9223 | Q28: 45536 | R28: 7191
A29: 45748 | B29: 45751 | C29: 7945 | D29: 0 | E29: 7945 | F29: 7832 | G29: 96 | H29: LECTURA NORMAL | K29: 45689 | L29: 10356 | Q29: 45566 | R29: 7831
A30: 45778 | B30: 45783 | C30: 8316 | D30: 0 | E30: 8316 | F30: 0 | G30: 0 | H30: LECTURA NORMAL | K30: 45717 | L30: 9117 | Q30: 45597 | R30: 8645
A31: 45809 | B31: 45814 | C31: 7731 | D31: 0 | E31: 7731 | F31: 0 | G31: 0 | H31: LECTURA NORMAL | K31: 45748 | L31: 7945 | Q31: 45627 | R31: 7572
A32: 45839 | B32: 45846 | C32: 8348 | D32: 0 | E32: 8348 | F32: 0 | G32: 0 | H32: LECTURA NORMAL | K32: 45778 | L32: 8316
A33: 45870 | B33: 45876 | C33: 8387 | D33: 0 | E33: 8387 | F33: 0 | G33: 0 | H33: LECTURA NORMAL | K33: 45809 | L33: 7731 | Q33: 45658 | R33: 9223
A34: 45901 | B34: 45905 | C34: 8674 | D34: 0 | E34: 8674 | F34: 0 | G34: 0 | H34: LECTURA NORMAL | K34: 45839 | L34: 8348 | Q34: 45689 | R34: 10356
A35: 45931 | B35: 45936 | C35: 8886 | D35: 0 | E35: 8886 | F35: 0 | G35: 0 | H35: LECTURA NORMAL | K35: 45870 | L35: 8387 | Q35: 45717 | R35: 9117
A36: 45962 | B36: 45968 | C36: 9752 | D36: 0 | E36: 9752 | F36: 0 | G36: 0 | H36: LECTURA NORMAL | K36: 45901 | L36: 8674 | Q36: 45748 | R36: 7945
A37: 45992 | B37: 45997 | C37: 9512 | D37: 0 | E37: 9512 | F37: 8505 | G37: 173 | H37: LECTURA NORMAL | K37: 45931 | L37: 8886 | Q37: 45778 | R37: 8316
K38: 45962 | L38: 9752 | Q38: 45809 | R38: 7731
K39: 45992 | L39: 9512
Q40: 45839 | R40: 8348
...
