Workbook

Sheet Valorizacion
A1: Valorización de mercado y depreciación de herramientas
A2: Cotización de retail en Chile, IVA incluido · 20 de octubre de 2026 · El valor de mercado usa el estado informado de cada herramienta
A3: Celdas amarillas: datos editables (estado y valor de reposición). Celdas verdes: se recalculan solas.
A5: N° | B5: Herramienta | C5: Categoría | D5: Stock | E5: Año de compra | F5: Años de uso | G5: Estado | H5: Valor de reposición | I5: Valor de mercado | J5: Depreciación $ | K5: Depreciación % | L5: Referencia cotizada | M5: Fuente | N5: Confianza
A6: 1 | B6: Soplete con manguera MAPP | C6: Gasfitería | D6: 1 | E6: 2022 | F6: =2026-E6 | G6: 0.8 | H6: 37090 | I6: =ROUND(H6*G6,0) | J6: =H6-I6 | K6: =IF(H6=0,0,J6/H6) | L6: Kit soplete MAPP con autoencendido y manguera | M6: Sodimac, kit vigente $37.090 (precio tachado $92.725, no se usa) | N6: Media
A7: 2 | B7: Sierra sable Bosch | C7: Construcción | D7: 1 | E7: 2021 | F7: =2026-E7 | G7: 0.8 | H7: 164212 | I7: =ROUND(H7*G7,0) | J7: =H7-I7 | K7: =IF(H7=0,0,J7/H7) | L7: Bosch GSA 1100 E, 1100 W, con cable | M7: Flexar $164.212 IVA incl. Kit inalámbrico en Sodimac $279.990 | N7: Media
A8: 3 | B8: Taladro inalámbrico DeWalt | C8: Eléctrica | D8: 1 | E8: 2021 | F8: =2026-E8 | G8: 0.6 | H8: 189990 | I8: =ROUND(H8*G8,0) | J8: =H8-I8 | K8: =IF(H8=0,0,J8/H8) | L8: DeWalt 20 V, 2 baterías y maleta | M8: Sodimac $189.990. Kits 20 V en oferta entre $125.000 y $240.000 | N8: Media
A9: 4 | B9: Taladro inalámbrico DeWalt | C9: Eléctrica | D9: 1 | E9: 2024 | F9: =2026-E9 | G9: 0.4 | H9: 189990 | I9: =ROUND(H9*G9,0) | J9: =H9-I9 | K9: =IF(H9=0,0,J9/H9) | L9: DeWalt 20 V, 2 baterías y maleta | M9: Misma referencia que la fila 3 | N9: Media
A10: 5 | B10: Rotomartillo Bosch | C10: Construcción | D10: 1 | E10: 2021 | F10: =2026-E10 | G10: 0.3 | H10: 169990 | I10: =ROUND(H10*G10,0) | J10: =H10-I10 | K10: =IF(H10=0,0,J10/H10) | L10: Bosch GBH 2-24 D, 820 W, SDS-plus | M10: Sodimac GBH 2-24 D + mandril $169.990 | N10: Alta
A11: 6 | B11: Rotomartillo Bosch | C11: Construcción | D11: 1 | E11: 2024 | F11: =2026-E11 | G11: 0.9 | H11: 169990 | I11: =ROUND(H11*G11,0) | J11: =H11-I11 | K11: =IF(H11=0,0,J11/H11) | L11: Bosch GBH 2-24 D, 820 W, SDS-plus | M11: Misma referencia que la fila 5 | N11: Alta
A12: 7 | B12: Escalera de aluminio | C12: Manual | D12: 1 | E12: 2021 | F12: =2026-E12 | G12: 0.9 | H12: 49990 | I12: =ROUND(H12*G12,0) | J12: =H12-I12 | K12: =IF(H12=0,0,J12/H12) | L12: Tijera de aluminio, 6 peldaños | M12: Sodimac $49.990. La altura no está en el inventario | N12: Baja
A13: 8 | B13: Escalera de aluminio | C13: Manual | D13: 1 | E13: 2021 | F13: =2026-E13 | G13: 0.9 | H13: 49990 | I13: =ROUND(H13*G13,0) | J13: =H13-I13 | K13: =IF(H13=0,0,J13/H13) | L13: Tijera de aluminio, 6 peldaños | M13: Misma referencia que la fila 7 | N13: Baja
A14: 9 | B14: Esmeril angular DeWalt | C14: Construcción | D14: 1 | E14: 2023 | F14: =2026-E14 | G14: 0.7 | H14: 119990 | I14: =ROUND(H14*G14,0) | J14: =H14-I14 | K14: =IF(H14=0,0,J14/H14) | L14: DeWalt DWE4120, 4-1/2 pulg., 900 W, con cable | M14: SBD Chile $119.990. Un DWE4020 de 800 W ronda $72.000 a $82.000 | N14: Media
A15: 10 | B15: Pistola calafatera | C15: Manual | D15: 1 | E15: 2026 | F15: =2026-E15 | G15: 0.9 | H15: 8990 | I15: =ROUND(H15*G15,0) | J15: =H15-I15 | K15: =IF(H15=0,0,J15/H15) | L15: Profesional antigoteo | M15: Sodimac $8.990 | N15: Alta
A16: 11 | B16: Multímetro digital UNI-T | C16: Eléctrica | D16: 1 | E16: 2025 | F16: =2026-E16 | G16: 0.9 | H16: 17990 | I16: =ROUND(H16*G16,0) | J16: =H16-I16 | K16: =IF(H16=0,0,J16/H16) | L16: UNI-T UT33C+ | M16: Molychile $17.990. El modelo no está indicado; un UT89X ronda $35.990 | N16: Media
A17: 12 | B17: Multímetro digital UNI-T | C17: Eléctrica | D17: 1 | E17: 2025 | F17: =2026-E17 | G17: 0.9 | H17: 17990 | I17: =ROUND(H17*G17,0) | J17: =H17-I17 | K17: =IF(H17=0,0,J17/H17) | L17: UNI-T UT33C+ | M17: Misma referencia que la fila 11 | N17: Media
A18: 13 | B18: Alicate universal | C18: Manual | D18: 1 | E18: — | F18: — | G18: 0.99 | H18: 6990 | I18: =ROUND(H18*G18,0) | J18: =H18-I18 | K18: =IF(H18=0,0,J18/H18) | L18: Universal 8 pulg., línea Total | M18: Geoconstructor $6.990 | N18: Media
A19: 14 | B19: Alicate de punta | C19: Manual | D19: 1 | E19: — | F19: — | G19: 0.99 | H19: 6490 | I19: =ROUND(H19*G19,0) | J19: =H19-I19 | K19: =IF(H19=0,0,J19/H19) | L19: Punta 6 a 8 pulg., línea Total/Ingco | M19: Estimado en el rango $5.990 a $7.990. Modelo no indicado | N19: Baja
A20: 15 | B20: Alicate cortante | C20: Manual | D20: 1 | E20: — | F20: — | G20: 0.8 | H20: 5990 | I20: =ROUND(H20*G20,0) | J20: =H20-I20 | K20: =IF(H20=0,0,J20/H20) | L20: Cortante 6 pulg., Total | M20: Ferroelectronic $5.990 | N20: Media
A21: 16 | B21: Alicate cortante | C21: Manual | D21: 1 | E21: — | F21: — | G21: 0.8 | H21: 5990 | I21: =ROUND(H21*G21,0) | J21: =H21-I21 | K21: =IF(H21=0,0,J21/H21) | L21: Cortante 6 pulg., Total | M21: Misma referencia que la fila 15 | N21: Media
A22: 17 | B22: Atornillador cruz | C22: Manual | D22: 1 | E22: — | F22: — | G22: 0.99 | H22: 2990 | I22: =ROUND(H22*G22,0) | J22: =H22-I22 | K22: =IF(H22=0,0,J22/H22) | L22: Destornillador Phillips individual | M22: Estimado de ferretería, rango habitual $2.000 a $4.000 | N22: Baja
A23: 18 | B23: Atornillador cruz | C23: Manual | D23: 1 | E23: — | F23: — | G23: 0.99 | H23: 2990 | I23: =ROUND(H23*G23,0) | J23: =H23-I23 | K23: =IF(H23=0,0,J23/H23) | L23: Destornillador Phillips individual | M23: Misma referencia que la fila 17 | N23: Baja
A24: 19 | B24: Atornillador paleta | C24: Manual | D24: 1 | E24: — | F24: — | G24: 0.99 | H24: 2990 | I24: =ROUND(H24*G24,0) | J24: =H24-I24 | K24: =IF(H24=0,0,J24/H24) | L24: Destornillador plano individual | M24: Estimado de ferretería, rango habitual $2.000 a $4.000 | N24: Baja
A25: 20 | B25: Atornillador paleta | C25: Manual | D25: 1 | E25: — | F25: — | G25: 0.99 | H25: 2990 | I25: =ROUND(H25*G25,0) | J25: =H25-I25 | K25: =IF(H25=0,0,J25/H25) | L25: Destornillador plano individual | M25: Misma referencia que la fila 19 | N25: Baja
A26: 21 | B26: Etiquetadora Brother | C26: Manual | D26: 1 | E26: — | F26: — | G26: 0.7 | H26: 41990 | I26: =ROUND(H26*G26,0) | J26: =H26-I26 | K26: =IF(H26=0,0,J26/H26) | L26: Brother P-touch PT-D210 | M26: Store Brother $41.990. Una PT-E industrial supera $150.000 | N26: Baja
A27: 22 | B27: Atornillador perillero | C27: Manual | D27: 1 | E27: — | F27: — | G27: 0.3 | H27: 3990 | I27: =ROUND(H27*G27,0) | J27: =H27-I27 | K27: =IF(H27=0,0,J27/H27) | L27: Destornillador perillero | M27: Estimado de ferretería, rango habitual $3.000 a $6.000 | N27: Baja
A28: 23 | B28: Atornillador perillero | C28: Manual | D28: 1 | E28: — | F28: — | G28: 0.99 | H28: 3990 | I28: =ROUND(H28*G28,0) | J28: =H28-I28 | K28: =IF(H28=0,0,J28/H28) | L28: Destornillador perillero | M28: Misma referencia que la fila 22 | N28: Baja
A29: 24 | B29: Tester de cable de red RJ45 | C29: Manual | D29: 1 | E29: — | F29: — | G29: 0.99 | H29: 8990 | I29: =ROUND(H29*G29,0) | J29: =H29-I29 | K29: =IF(H29=0,0,J29/H29) | L29: Tester de continuidad RJ45/RJ11 | M29: Cinet Onten OTN-E921 $8.300, redondeado a $8.990 | N29: Media
A30: 25 | B30: Cautín 60 W | C30: Eléctrica | D30: 1 | E30: 2024 | F30: =2026-E30 | G30: 0.3 | H30: 8990 | I30: =ROUND(H30*G30,0) | J30: =H30-I30 | K30: =IF(H30=0,0,J30/H30) | L30: Cautín 60 W con ajuste de temperatura | M30: Global Electrónica 60ADJ $8.990 | N30: Alta
A31: 26 | B31: Cautín 60 W | C31: Eléctrica | D31: 1 | E31: 2023 | F31: =2026-E31 | G31: 0.3 | H31: 8990 | I31: =ROUND(H31*G31,0) | J31: =H31-I31 | K31: =IF(H31=0,0,J31/H31) | L31: Cautín 60 W con ajuste de temperatura | M31: Misma referencia que la fila 25 | N31: Alta
A32: 27 | B32: Termofusionadora PPR D20 a D63 | C32: Gasfitería | D32: 1 | E32: 2020 | F32: =2026-E32 | G32: 0.5 | H32: 76850 | I32: =ROUND(H32*G32,0) | J32: =H32-I32 | K32: =IF(H32=0,0,J32/H32) | L32: Digital 20-63 mm, 800 a 1000 W | M32: Sodimac Hoffens $76.850. Canale 1000 W $85.000 | N32: Media
A33: 28 | B33: Termofusionadora PPR D75 a D110 | C33: Gasfitería | D33: 1 | E33: 2020 | F33: =2026-E33 | G33: 0.8 | H33: 160531 | I33: =ROUND(H33*G33,0) | J33: =H33-I33 | K33: =IF(H33=0,0,J33/H33) | L33: Digital portátil 75-110 mm | M33: IMPUS $160.531. Tehmco $116.102. No es bancada hidráulica | N33: Media
A34: 29 | B34: Soldadora HYM 160 A | C34: Construcción | D34: 1 | E34: 2020 | F34: =2026-E34 | G34: 0.5 | H34: 204790 | I34: =ROUND(H34*G34,0) | J34: =H34-I34 | K34: =IF(H34=0,0,J34/H34) | L34: Hyundai inverter HYMMA-160 | M34: Herramientas Chile $204.790. Ferramak $229.990 | N34: Alta
A35: 30 | B35: Careta de soldador | C35: Construcción | D35: 1 | E35: 2023 | F35: =2026-E35 | G35: 0.6 | H35: 19990 | I35: =ROUND(H35*G35,0) | J35: =H35-I35 | K35: =IF(H35=0,0,J35/H35) | L35: Careta fotosensible de entrada | M35: Retail habitual $16.000 a $30.000. El tipo no está indicado | N35: Baja
A36: 31 | B36: Bomba sumergible | C36: Gasfitería | D36: 1 | E36: 2024 | F36: =2026-E36 | G36: 0.9 | H36: 112990 | I36: =ROUND(H36*G36,0) | J36: =H36-I36 | K36: =IF(H36=0,0,J36/H36) | L36: 1 HP para agua sucia | M36: Sodimac Bercatti $112.990. La potencia no está indicada | N36: Baja
A37: 32 | B37: Toldo impermeable | C37: Gasfitería | D37: 1 | E37: 2026 | F37: =2026-E37 | G37: 0.99 | H37: 39990 | I37: =ROUND(H37*G37,0) | J37: =H37-I37 | K37: =IF(H37=0,0,J37/H37) | L37: Plegable 3x3 m | M37: Sodimac $39.990. La medida no está indicada | N37: Baja
A38: 33 | B38: Llave stilson 18" | C38: Gasfitería | D38: 1 | E38: 2019 | F38: =2026-E38 | G38: 0.99 | H38: 15990 | I38: =ROUND(H38*G38,0) | J38: =H38-I38 | K38: =IF(H38=0,0,J38/H38) | L38: Stilson 18" | M38: Ferroelectronic $15.990. Ingco entre $13.491 y $23.199 | N38: Alta
A39: 34 | B39: Llave stilson 36" | C39: Gasfitería | D39: 1 | E39: 2020 | F39: =2026-E39 | G39: 0.99 | H39: 49990 | I39: =ROUND(H39*G39,0) | J39: =H39-I39 | K39: =IF(H39=0,0,J39/H39) | L39: Stilson 36", Ingco HPW0836 | M39: Publicado entre $42.990 y $58.499. Se usa el punto medio | N39: Media
A40: 35 | B40: Llave francesa 12" | C40: Gasfitería | D40: 1 | E40: 2021 | F40: =2026-E40 | G40: 0.99 | H40: 14990 | I40: =ROUND(H40*G40,0) | J40: =H40-I40 | K40: =IF(H40=0,0,J40/H40) | L40: Francesa de acero 12" | M40: Sodimac $14.990 | N40: Alta
A41: 36 | B41: Odómetro de rueda | C41: Manual | D41: 1 | E41: 2022 | F41: =2026-E41 | G41: 0.99 | H41: 16990 | I41: =ROUND(H41*G41,0) | J41: =H41-I41 | K41: =IF(H41=0,0,J41/H41) | L41: Rueda analógica | M41: Crownman $16.990 | N41: Media
...

Sheet Resumen
A1: Resumen por categoría
A2: Fecha de cotización: 20 de octubre de 2026. Moneda: pesos chilenos con IVA.
A4: Categoría | B4: Ítems | C4: Valor de reposición | D4: Valor de mercado | E4: Depreciación $ | F4: Depreciación %
A5: Gasfitería | B5: =COUNTIF(Valorizacion!C:C,A5) | C5: =SUMIF(Valorizacion!C:C,A5,Valorizacion!H:H) | D5: =SUMIF(Valorizacion!C:C,A5,Valorizacion!I:I) | E5: =SUMIF(Valorizacion!C:C,A5,Valorizacion!J:J) | F5: =IF(C5=0,0,E5/C5)
A6: Construcción | B6: =COUNTIF(Valorizacion!C:C,A6) | C6: =SUMIF(Valorizacion!C:C,A6,Valorizacion!H:H) | D6: =SUMIF(Valorizacion!C:C,A6,Valorizacion!I:I) | E6: =SUMIF(Valorizacion!C:C,A6,Valorizacion!J:J) | F6: =IF(C6=0,0,E6/C6)
A7: Eléctrica | B7: =COUNTIF(Valorizacion!C:C,A7) | C7: =SUMIF(Valorizacion!C:C,A7,Valorizacion!H:H) | D7: =SUMIF(Valorizacion!C:C,A7,Valorizacion!I:I) | E7: =SUMIF(Valorizacion!C:C,A7,Valorizacion!J:J) | F7: =IF(C7=0,0,E7/C7)
A8: Manual | B8: =COUNTIF(Valorizacion!C:C,A8) | C8: =SUMIF(Valorizacion!C:C,A8,Valorizacion!H:H) | D8: =SUMIF(Valorizacion!C:C,A8,Valorizacion!I:I) | E8: =SUMIF(Valorizacion!C:C,A8,Valorizacion!J:J) | F8: =IF(C8=0,0,E8/C8)
A9: Total | B9: =SUM(B5:B8) | C9: =SUM(C5:C8) | D9: =SUM(D5:D8) | E9: =SUM(E5:E8) | F9: =IF(C9=0,0,E9/C9)
A28: Cómo se calcula
A29: Valor de reposición: precio vigente de un equipo equivalente nuevo, en retail de Chile, con IVA, cotizado en octubre de 2026.
A30: Estado: porcentaje informado en el inventario. Se interpreta como la fracción del valor nuevo que el equipo todavía conserva.
A31: Valor de mercado = valor de reposición × estado. Es lo que el equipo vale hoy, en la condición declarada.
A32: Depreciación $ = valor de reposición − valor de mercado. Depreciación % = 1 − estado.
A33: No se aplica una segunda depreciación por antigüedad. El estado ya recoge el desgaste. Una línea recta por años contradice, por ejemplo, el rotomartillo de 2024 que está al 90%.
A34: Esto es un valor de mercado. No es la depreciación tributaria del SII ni el valor libro contable.
A35: Donde el inventario no trae modelo, medida o potencia, se usa la referencia más habitual de obra y se marca la confianza como Baja o Media.
A36: Las celdas amarillas de la hoja Valorizacion se pueden corregir. El valor de mercado y la depreciación se recalculan.

Sheet Fuentes
A1: Referencia usada en cada ítem
A3: N° | B3: Herramienta | C3: Confianza | D3: Referencia | E3: Fuente y comentario
A4: 1 | B4: Soplete con manguera MAPP | C4: Media | D4: Kit soplete MAPP con autoencendido y manguera | E4: Sodimac, kit vigente $37.090 (precio tachado $92.725, no se usa)
A5: 2 | B5: Sierra sable Bosch | C5: Media | D5: Bosch GSA 1100 E, 1100 W, con cable | E5: Flexar $164.212 IVA incl. Kit inalámbrico en Sodimac $279.990
A6: 3 | B6: Taladro inalámbrico DeWalt | C6: Media | D6: DeWalt 20 V, 2 baterías y maleta | E6: Sodimac $189.990. Kits 20 V en oferta entre $125.000 y $240.000
A7: 4 | B7: Taladro inalámbrico DeWalt | C7: Media | D7: DeWalt 20 V, 2 baterías y maleta | E7: Misma referencia que la fila 3
A8: 5 | B8: Rotomartillo Bosch | C8: Alta | D8: Bosch GBH 2-24 D, 820 W, SDS-plus | E8: Sodimac GBH 2-24 D + mandril $169.990
A9: 6 | B9: Rotomartillo Bosch | C9: Alta | D9: Bosch GBH 2-24 D, 820 W, SDS-plus | E9: Misma referencia que la fila 5
A10: 7 | B10: Escalera de aluminio | C10: Baja | D10: Tijera de aluminio, 6 peldaños | E10: Sodimac $49.990. La altura no está en el inventario
A11: 8 | B11: Escalera de aluminio | C11: Baja | D11: Tijera de aluminio, 6 peldaños | E11: Misma referencia que la fila 7
A12: 9 | B12: Esmeril angular DeWalt | C12: Media | D12: DeWalt DWE4120, 4-1/2 pulg., 900 W, con cable | E12: SBD Chile $119.990. Un DWE4020 de 800 W ronda $72.000 a $82.000
A13: 10 | B13: Pistola calafatera | C13: Alta | D13: Profesional antigoteo | E13: Sodimac $8.990
A14: 11 | B14: Multímetro digital UNI-T | C14: Media | D14: UNI-T UT33C+ | E14: Molychile $17.990. El modelo no está indicado; un UT89X ronda $35.990
A15: 12 | B15: Multímetro digital UNI-T | C15: Media | D15: UNI-T UT33C+ | E15: Misma referencia que la fila 11
... A39: 36 | B39: Odómetro de rueda | C39: Media | D39: Rueda analógica | E39: Crownman $16.990
